2022-02-15 14:27:17,477 INFO    MainThread:206466 [internal.py:wandb_internal():91] W&B internal server running at pid: 206466, started at: 2022-02-15 14:27:17.477090
2022-02-15 14:27:17,478 DEBUG   HandlerThread:206466 [handler.py:handle_request():120] handle_request: check_version
2022-02-15 14:27:17,478 INFO    WriterThread:206466 [datastore.py:open_for_write():77] open: /workspace/graph-neural-pde/src/wandb/run-20220215_142716-test_run_log_nfe/run-test_run_log_nfe.wandb
2022-02-15 14:27:17,479 DEBUG   SenderThread:206466 [sender.py:send():160] send: header
2022-02-15 14:27:17,479 DEBUG   SenderThread:206466 [sender.py:send():160] send: request
2022-02-15 14:27:17,479 DEBUG   SenderThread:206466 [sender.py:send_request():169] send_request: check_version
2022-02-15 14:27:17,687 DEBUG   SenderThread:206466 [sender.py:send():160] send: run
2022-02-15 14:27:18,233 ERROR   SenderThread:206466 [internal_api.py:execute():127] 404 response executing GraphQL.
2022-02-15 14:27:18,235 ERROR   SenderThread:206466 [internal_api.py:execute():128] {"errors":[{"message":"project not found","path":["upsertBucket"]}],"data":{"upsertBucket":null}}
2022-02-15 14:27:18,689 INFO    HandlerThread:206466 [handler.py:finish():624] shutting down handler
2022-02-15 14:27:18,693 INFO    WriterThread:206466 [datastore.py:close():258] close: /workspace/graph-neural-pde/src/wandb/run-20220215_142716-test_run_log_nfe/run-test_run_log_nfe.wandb
2022-02-15 14:27:18,693 ERROR   MainThread:206466 [internal.py:wandb_internal():158] Thread SenderThread:
Traceback (most recent call last):
  File "/opt/conda/lib/python3.6/site-packages/wandb/old/retry.py", line 96, in __call__
    result = self._call_fn(*args, **kwargs)
  File "/opt/conda/lib/python3.6/site-packages/wandb/sdk/internal/internal_api.py", line 130, in execute
    six.reraise(*sys.exc_info())
  File "/opt/conda/lib/python3.6/site-packages/six.py", line 703, in reraise
    raise value
  File "/opt/conda/lib/python3.6/site-packages/wandb/sdk/internal/internal_api.py", line 124, in execute
    return self.client.execute(*args, **kwargs)
  File "/opt/conda/lib/python3.6/site-packages/wandb/vendor/gql-0.2.0/gql/client.py", line 52, in execute
    result = self._get_result(document, *args, **kwargs)
  File "/opt/conda/lib/python3.6/site-packages/wandb/vendor/gql-0.2.0/gql/client.py", line 60, in _get_result
    return self.transport.execute(document, *args, **kwargs)
  File "/opt/conda/lib/python3.6/site-packages/wandb/vendor/gql-0.2.0/gql/transport/requests.py", line 39, in execute
    request.raise_for_status()
  File "/opt/conda/lib/python3.6/site-packages/requests/models.py", line 941, in raise_for_status
    raise HTTPError(http_error_msg, response=self)
requests.exceptions.HTTPError: 404 Client Error: Not Found for url: https://api.wandb.ai/graphql

During handling of the above exception, another exception occurred:

Traceback (most recent call last):
  File "/opt/conda/lib/python3.6/site-packages/wandb/apis/normalize.py", line 24, in wrapper
    return func(*args, **kwargs)
  File "/opt/conda/lib/python3.6/site-packages/wandb/sdk/internal/internal_api.py", line 886, in upsert_run
    response = self.gql(mutation, variable_values=variable_values, **kwargs)
  File "/opt/conda/lib/python3.6/site-packages/wandb/old/retry.py", line 105, in __call__
    if not check_retry_fn(e):
  File "/opt/conda/lib/python3.6/site-packages/wandb/util.py", line 715, in no_retry_auth
    raise CommError("Permission denied, ask the project owner to grant you access")
wandb.errors.CommError: Permission denied, ask the project owner to grant you access

During handling of the above exception, another exception occurred:

Traceback (most recent call last):
  File "/opt/conda/lib/python3.6/site-packages/wandb/sdk/internal/internal_util.py", line 54, in run
    self._run()
  File "/opt/conda/lib/python3.6/site-packages/wandb/sdk/internal/internal_util.py", line 95, in _run
    self._process(record)
  File "/opt/conda/lib/python3.6/site-packages/wandb/sdk/internal/internal.py", line 279, in _process
    self._sm.send(record)
  File "/opt/conda/lib/python3.6/site-packages/wandb/sdk/internal/sender.py", line 162, in send
    send_handler(record)
  File "/opt/conda/lib/python3.6/site-packages/wandb/sdk/internal/sender.py", line 541, in send_run
    self._init_run(run, config_value_dict)
  File "/opt/conda/lib/python3.6/site-packages/wandb/sdk/internal/sender.py", line 577, in _init_run
    commit=repo.last_commit,
  File "/opt/conda/lib/python3.6/site-packages/wandb/apis/normalize.py", line 62, in wrapper
    six.reraise(CommError, CommError(message, err), sys.exc_info()[2])
  File "/opt/conda/lib/python3.6/site-packages/six.py", line 702, in reraise
    raise value.with_traceback(tb)
  File "/opt/conda/lib/python3.6/site-packages/wandb/apis/normalize.py", line 24, in wrapper
    return func(*args, **kwargs)
  File "/opt/conda/lib/python3.6/site-packages/wandb/sdk/internal/internal_api.py", line 886, in upsert_run
    response = self.gql(mutation, variable_values=variable_values, **kwargs)
  File "/opt/conda/lib/python3.6/site-packages/wandb/old/retry.py", line 105, in __call__
    if not check_retry_fn(e):
  File "/opt/conda/lib/python3.6/site-packages/wandb/util.py", line 715, in no_retry_auth
    raise CommError("Permission denied, ask the project owner to grant you access")
wandb.errors.CommError: Permission denied, ask the project owner to grant you access
2022-02-15 14:27:20,511 INFO    MainThread:206466 [internal.py:handle_exit():78] Internal process exited
